Workbook

Sheet Cover
B3: Cheesecoins Protocol — Financial Projections
B4: Version v3 · Generated 2026-05-05 · Dynamic treasury + Balance Sheet
B6: Project | C6: Cheesecoins Protocol
B7: Network | C7: Arbitrum One mainnet (live since 2026-03-25)
B8: Token | C8: CURD (200,000,000 supply)
B9: Treasury | C9: Gnosis Safe 0x6C64ACd0Be573D7c90d9b0c6fFDf2E69573871D2
B10: Founder | C10: Gregory Garner — Nubians North farm, Ontario
B11: Funding | C11: Pre-grant. Applying to Arbitrum Advanced Growth ($150k)
B13: What's new in v3
B14: • Balance Sheet wired in — assets / liabilities / equity for Y1, Y2, Y3 year-end
B15: • Dynamic USDC treasury — accumulates from real CURD sales + fees, not a flat dial
B16: • CURD-backing-per-circulating-token metric — shows speculative upside as treasury grows
B17: • T-bill yield calc now references the rolling treasury balance (more accurate)
B20: How to use
B21: 1. Open Assumptions — yellow cells are user inputs.
B22: 2. Change any yellow cell; downstream sheets recalculate via formulas.
B23: 3. Income Statement and Balance Sheet are the primary outputs.
B24: 4. Treasury Flow shows how USDC builds up year-over-year — this drives T-bill yield.
B25: 5. Use the Scenarios sheet to compare conservative / base / aggressive.
B28: Sheets in this workbook
B29: Cover | C29: this page
B30: Assumptions | C30: input dials (partner growth, fee rates, expense lines, treasury params)
B31: Treasury Flow | C31: USDC accumulation + T-bill deployment + yield distribution (rolling Y1→Y3)
B32: Revenue | C32: per-stream revenue calculation by year
B33: Expenses | C33: per-category expense calculation by year
B34: Income Statement | C34: consolidated P&L Y1 / Y2 / Y3 + 3-yr totals
B35: Cashflow Y1 | C35: monthly cashflow May 2026 – Apr 2027
B36: Balance Sheet | C36: assets / liabilities / equity + CURD-backing-per-token
B37: Scenarios | C37: conservative / base / aggressive comparison
B38: Token Treasury | C38: CURD allocation movements

Sheet Assumptions
B2: ASSUMPTIONS — yellow cells are user inputs
B3: Every downstream sheet references this. USDC treasury balance is now COMPUTED in Treasury Flow, not input.
B5: Driver | C5: Year 1 | D5: Year 2 | E5: Year 3 | F5: Notes
B6: PARTNER GROWTH (Greg's scaled trajectory — assumes AI-leveraged onboarding)
B7: Partners — Vendors (tier 1) | C7: 10 | D7: 1000 | E7: 10000 | F7: Sells inputs to producers
B8: Partners — Producers (tier 2) | C8: 4 | D8: 400 | E8: 4000 | F8: Farms
B9: Partners — Processors (tier 3) | C9: 4 | D9: 10 | E9: 100 | F9: Cheese plants, abattoirs
B10: Partners — Distributors (tier 4) | C10: 5 | D10: 10 | E10: 300 | F10: Wholesalers
B11: Partners — Merchants (tier 5) | C11: 30 | D11: 3000 | E11: 30000 | F11: Retail / direct-to-consumer
B12: MONTHLY GMV PER PARTNER (USD)
B13: Avg monthly GMV — Vendor | C13: 1500 | D13: 5000 | E13: 7500 | F13: Conservative SMB ag estimate
B14: Avg monthly GMV — Producer | C14: 3000 | D14: 4000 | E14: 5000 | F14: Farm direct sales
B15: Avg monthly GMV — Processor | C15: 5000 | D15: 6500 | E15: 9000 | F15: Higher-value processing
B16: Avg monthly GMV — Distributor | C16: 8000 | D16: 10000 | E16: 13000 | F16: Bulk wholesale
B17: Avg monthly GMV — Merchant | C17: 2000 | D17: 5000 | E17: 7000 | F17: Retail per location
B18: PROTOCOL FEE STRUCTURE
B19: Commerce NFT mint fee (% of project sale) | C19: 0.05 | D19: 0.05 | E19: 0.05 | F19: Per Phase 2 spec
B20: Capital/Land NFT mint fee (%) | C20: 0.025 | D20: 0.025 | E20: 0.025 | F20: Per Phase 2 spec
B21: CurdDirectSale spread (%) | C21: 0.01 | D21: 0.01 | E21: 0.01 | F21: USDC→CURD spread
B22: FX hedge premium (% per settlement) | C22: 0 | D22: 0.004 | E22: 0.004 | F22: Phase 2 — Y1 not live
B23: NFT PROJECT ACTIVITY
B24: # Commerce NFT projects launched/yr | C24: 5 | D24: 500 | E24: 4000 | F24: Roughly = active partner-issuers
B25: Avg Commerce NFT raise per project (USD) | C25: 20000 | D25: 40000 | E25: 80000 | F25: Sold-out target
B26: # Capital/Land NFT projects launched/yr | C26: 2 | D26: 100 | E26: 1000 | F26: Larger, less frequent
B27: Avg Capital/Land raise per project (USD) | C27: 500000 | D27: 1000000 | E27: 1500000 | F27: Equipment / land partial-rights
B28: CurdDirectSale buyers/yr | C28: 1000 | D28: 50000 | E28: 1000000 | F28: USDC→CURD direct purchasers
B29: Avg CurdDirectSale purchase (USD) | C29: 100 | D29: 250 | E29: 350 | F29: Per-buyer avg
B30: SETTLEMENT INDEX (Phase 2/3 — subscription revenue)
B31: # subscriber protocols | C31: 0 | D31: 3 | E31: 10 | F31: Y1 not live; Y2 mid-year launch
B32: Avg monthly subscription per protocol (USD) | C32: 0 | D32: 500 | E32: 750 | F32: Conservative tier
B33: Active months in year | C33: 0 | D33: 6 | E33: 12 | F33: Y2 = mid-year launch
B34: TREASURY MANAGEMENT (T-bill deployment of USDC reserves)
B35: T-bill APY (%) | C35: 0.045 | D35: 0.045 | E35: 0.045 | F35: Tokenized USDC T-bill products (Ondo USDY, Mountain USDM, BlackRock BUIDL)
B36: Protocol's share of yield (%) | C36: 0.3 | D36: 0.3 | E36: 0.3 | F36: 30% to protocol treasury, 70% to staked CURD holders
B37: Stakers' share of yield (%) | C37: 0.7 | D37: 0.7 | E37: 0.7 | F37: Routed via BootstrapYieldPool / TreasuryRateAdvisor
B38: % of USDC deployed in T-bills | C38: 0.5 | D38: 0.8 | E38: 0.9 | F38: Rest held as operating liquidity. Ramps as protocol matures
B39: AI-LEVERAGED OPERATIONS — Customer Acquisition
B40: Customer Acquisition Cost per partner (USD) | C40: 50 | D40: 30 | E40: 20 | F40: AI-assisted outreach + auto-onboarding; declines as scale + reputation grow
B41: Baseline marketing budget (non-CAC, USD/yr) | C41: 30000 | D41: 60000 | E41: 120000 | F41: Brand + content + events. Decoupled from per-partner CAC
B42: EXPENSES — STAFF & OPS (lean, AI-leveraged)
...

Sheet Treasury Flow
B2: USDC TREASURY FLOW & T-BILL YIELD
B3: USDC accumulates from CURD sales + fees + grant. Deployed into tokenized T-bills. Yield routes to stakers + protocol.
B5: Flow | C5: Year 1 | D5: Year 2 | E5: Year 3 | F5: Notes
B6: USDC INFLOWS (Annual)
B7: CurdDirectSale revenue (USDC) | C7: =Assumptions!C28*Assumptions!C29 | D7: =Assumptions!D28*Assumptions!D29 | E7: =Assumptions!E28*Assumptions!E29 | F7: =buyers × avg purchase
B8: Commerce NFT fees (USDC, protocol's 5%) | C8: =Assumptions!C24*Assumptions!C25*Assumptions!C19 | D8: =Assumptions!D24*Assumptions!D25*Assumptions!D19 | E8: =Assumptions!E24*Assumptions!E25*Assumptions!E19 | F8: =projects × avg raise × fee%
B9: Capital/Land NFT fees (USDC, protocol's 2.5%) | C9: =Assumptions!C26*Assumptions!C27*Assumptions!C20 | D9: =Assumptions!D26*Assumptions!D27*Assumptions!D20 | E9: =Assumptions!E26*Assumptions!E27*Assumptions!E20 | F9: =projects × avg raise × fee%
B10: FX hedge premium (USDC) | C10: =12*(Assumptions!C7*Assumptions!C13+Assumptions!C8*Assumptions!C14+Assumptions!C9*Assumptions!C15+Assumptions!C10*Assumptions!C16+Assumptions!C11*Assumptions!C17)*Assumptions!C22 | D10: =12*(Assumptions!D7*Assumptions!D13+Assumptions!D8*Assumptions!D14+Assumptions!D9*Assumptions!D15+Assumptions!D10*Assumptions!D16+Assumptions!D11*Assumptions!D17)*Assumptions!D22 | E10: =12*(Assumptions!E7*Assumptions!E13+Assumptions!E8*Assumptions!E14+Assumptions!E9*Assumptions!E15+Assumptions!E10*Assumptions!E16+Assumptions!E11*Assumptions!E17)*Assumptions!E22 | F10: =total GMV × premium%
B11: Subscription Index fees (USDC) | C11: =Assumptions!C31*Assumptions!C32*Assumptions!C33 | D11: =Assumptions!D31*Assumptions!D32*Assumptions!D33 | E11: =Assumptions!E31*Assumptions!E32*Assumptions!E33 | F11: =protocols × monthly × active months
B12: Grant inflow (USDC) | C12: =Assumptions!C53 | D12: =Assumptions!D53 | E12: =Assumptions!E53 | F12: Y1 only
B13: TOTAL USDC INFLOWS | C13: =SUM(C7:C12) | D13: =SUM(D7:D12) | E13: =SUM(E7:E12)
B14: USDC OUTFLOWS (operating expenses paid in USDC)
B15: Operating expenses paid in USDC | C15: =Assumptions!C43+Assumptions!C44+Assumptions!C45+Assumptions!C46*12+Assumptions!C49*12+Assumptions!C47+Assumptions!C48+Assumptions!C50+Assumptions!C51+Assumptions!C41+(Assumptions!C7+Assumptions!C8+Assumptions!C9+Assumptions!C10+Assumptions!C11)*Assumptions!C40 | D15: =Assumptions!D43+Assumptions!D44+Assumptions!D45+Assumptions!D46*12+Assumptions!D49*12+Assumptions!D47+Assumptions!D48+Assumptions!D50+Assumptions!D51+Assumptions!D41+((Assumptions!D7+Assumptions!D8+Assumptions!D9+Assumptions!D10+Assumptions!D11)-(Assumptions!C7+Assumptions!C8+Assumptions!C9+Assumptions!C10+Assumptions!C11))*Assumptions!D40 | E15: =Assumptions!E43+Assumptions!E44+Assumptions!E45+Assumptions!E46*12+Assumptions!E49*12+Assumptions!E47+Assumptions!E48+Assumptions!E50+Assumptions!E51+Assumptions!E41+((Assumptions!E7+Assumptions!E8+Assumptions!E9+Assumptions!E10+Assumptions!E11)-(Assumptions!D7+Assumptions!D8+Assumptions!D9+Assumptions!D10+Assumptions!D11))*Assumptions!E40 | F15: =all USD expenses (yield-to-stakers paid in CURD, excluded)
B16: USDC TREASURY POSITION (rolling Y1→Y3)
B17: Opening balance | C17: 0 | D17: =C18 | E17: =D18
B18: Closing balance | C18: =C17+C13-C15 | D18: =D17+D13-D15 | E18: =E17+E13-E15 | F18: =opening + inflows − USDC opex
B19: Average balance (used for T-bill yield) | C19: =(C17+C18)/2 | D19: =(D17+D18)/2 | E19: =(E17+E18)/2
B20: T-BILL DEPLOYMENT & YIELD
B21: USDC deployed in T-bills | C21: =C19*Assumptions!C38 | D21: =D19*Assumptions!D38 | E21: =E19*Assumptions!E38 | F21: =avg balance × deploy%
B22: Gross T-bill yield | C22: =C21*Assumptions!C35 | D22: =D21*Assumptions!D35 | E22: =E21*Assumptions!E35 | F22: =deployed × APY
B23: → Protocol's share (revenue line) | C23: =C22*Assumptions!C36 | D23: =D22*Assumptions!D36 | E23: =E22*Assumptions!E36
B24: → Stakers' share (paid via BootstrapYieldPool) | C24: =C22*Assumptions!C37 | D24: =D22*Assumptions!D37 | E24: =E22*Assumptions!E37

Sheet Revenue
B2: REVENUE PROJECTIONS
B3: Formulas reference Assumptions and Treasury Flow.
B5: Revenue Stream | C5: Year 1 | D5: Year 2 | E5: Year 3 | F5: Calculation
B6: STREAM 1 — NFT MINT FEES
B7: Commerce NFT mint fees | C7: ='Treasury Flow'!C8 | D7: ='Treasury Flow'!D8 | E7: ='Treasury Flow'!E8 | F7: From Treasury Flow
B8: Capital/Land NFT mint fees | C8: ='Treasury Flow'!C9 | D8: ='Treasury Flow'!D9 | E8: ='Treasury Flow'!E9 | F8: From Treasury Flow
B9: STREAM 2 — DIRECT SALE SPREAD (1% on CurdDirectSale)
B10: CurdDirectSale spread | C10: =Assumptions!C28*Assumptions!C29*Assumptions!C21 | D10: =Assumptions!D28*Assumptions!D29*Assumptions!D21 | E10: =Assumptions!E28*Assumptions!E29*Assumptions!E21 | F10: =buyers × avg purchase × spread%
B11: STREAM 3 — FX HEDGE PREMIUM (Phase 2)
B12: FX hedge premium revenue | C12: ='Treasury Flow'!C10 | D12: ='Treasury Flow'!D10 | E12: ='Treasury Flow'!E10 | F12: From Treasury Flow
B13: STREAM 4 — SETTLEMENT INDEX SUBSCRIPTION
B14: Settlement Index subscriptions | C14: ='Treasury Flow'!C11 | D14: ='Treasury Flow'!D11 | E14: ='Treasury Flow'!E11 | F14: From Treasury Flow
B15: STREAM 5 — T-BILL YIELD (protocol's share)
B16: Protocol's share of T-bill yield | C16: ='Treasury Flow'!C23 | D16: ='Treasury Flow'!D23 | E16: ='Treasury Flow'!E23 | F16: From Treasury Flow — uses dynamic avg USDC balance
B17: STREAM 6 — GRANT (one-time, Y1)
B18: Arbitrum Foundation grant | C18: =Assumptions!C53 | D18: =Assumptions!D53 | E18: =Assumptions!E53 | F18: Treated separately — non-operating inflow
B20: TOTALS
B21: OPERATING REVENUE (excl. grant) | C21: =C7+C8+C10+C12+C14+C16 | D21: =D7+D8+D10+D12+D14+D16 | E21: =E7+E8+E10+E12+E14+E16
B22: TOTAL INFLOWS (incl. grant) | C22: =C21+C18 | D22: =D21+D18 | E22: =E21+E18

Sheet Expenses
B2: EXPENSE PROJECTIONS
B3: Formulas reference Assumptions and Treasury Flow.
B5: Expense Category | C5: Year 1 | D5: Year 2 | E5: Year 3 | F5: Calculation
B6: RECURRING — STAFF & OPS
B7: Founder pay | C7: =Assumptions!C43 | D7: =Assumptions!D43 | E7: =Assumptions!E43
B8: Contractor capacity | C8: =Assumptions!C44 | D8: =Assumptions!D44 | E8: =Assumptions!E44
B9: Ops stipend | C9: =Assumptions!C45 | D9: =Assumptions!D45 | E9: =Assumptions!E45
B10: RECURRING — INFRASTRUCTURE
B11: Hosting & infra (annualized) | C11: =Assumptions!C46*12 | D11: =Assumptions!D46*12 | E11: =Assumptions!E46*12 | F11: =monthly × 12
B12: CME data license (annualized) | C12: =Assumptions!C49*12 | D12: =Assumptions!D49*12 | E12: =Assumptions!E49*12 | F12: =monthly × 12
B13: CUSTOMER ACQUISITION (scales with new partners)
B14: New partners onboarded (informational) | C14: =(Assumptions!C7+Assumptions!C8+Assumptions!C9+Assumptions!C10+Assumptions!C11) | D14: =(Assumptions!D7+Assumptions!D8+Assumptions!D9+Assumptions!D10+Assumptions!D11)-(Assumptions!C7+Assumptions!C8+Assumptions!C9+Assumptions!C10+Assumptions!C11) | E14: =(Assumptions!E7+Assumptions!E8+Assumptions!E9+Assumptions!E10+Assumptions!E11)-(Assumptions!D7+Assumptions!D8+Assumptions!D9+Assumptions!D10+Assumptions!D11) | F14: =total - prior year
B15: Customer acquisition cost (CAC × new partners) | C15: =Expenses!C14*Assumptions!C40 | D15: =Expenses!D14*Assumptions!D40 | E15: =Expenses!E14*Assumptions!E40 | F15: =new partners × CAC per partner
B16: Baseline marketing & promotion | C16: =Assumptions!C41 | D16: =Assumptions!D41 | E16: =Assumptions!E41 | F16: Brand, content, events — decoupled from CAC
B17: RECURRING — LEGAL / AUDIT
B18: Legal / compliance | C18: =Assumptions!C47 | D18: =Assumptions!D47 | E18: =Assumptions!E47
B19: Audit costs | C19: =Assumptions!C48 | D19: =Assumptions!D48 | E19: =Assumptions!E48
B20: YIELD DISTRIBUTION (T-bill yield routed to staked CURD holders)
B21: Yield paid to staked CURD holders | C21: ='Treasury Flow'!C24 | D21: ='Treasury Flow'!D24 | E21: ='Treasury Flow'!E24 | F21: From Treasury Flow
B22: ONE-TIME (Y1, mostly grant-covered)
B23: CME seed | C23: =Assumptions!C50 | D23: =Assumptions!D50 | E23: =Assumptions!E50
B24: Liquidity tranche | C24: =Assumptions!C51 | D24: =Assumptions!D51 | E24: =Assumptions!E51
B26: TOTALS
B27: TOTAL EXPENSES | C27: =C7+C8+C9+C11+C12+C15+C16+C18+C19+C21+C23+C24 | D27: =D7+D8+D9+D11+D12+D15+D16+D18+D19+D21+D23+D24 | E27: =E7+E8+E9+E11+E12+E15+E16+E18+E19+E21+E23+E24

Sheet Income Statement
B2: INCOME STATEMENT — 3-year projection
B3: Pulled from Revenue and Expenses sheets.
B5: Line Item | C5: Year 1 | D5: Year 2 | E5: Year 3 | F5: 3-Yr Total
B6: REVENUE
B7: Commerce NFT mint fees | C7: =Revenue!C7 | D7: =Revenue!D7 | E7: =Revenue!E7 | F7: =SUM(C7:E7)
B8: Capital/Land NFT mint fees | C8: =Revenue!C8 | D8: =Revenue!D8 | E8: =Revenue!E8 | F8: =SUM(C8:E8)
B9: CurdDirectSale spread | C9: =Revenue!C10 | D9: =Revenue!D10 | E9: =Revenue!E10 | F9: =SUM(C9:E9)
B10: FX hedge premium | C10: =Revenue!C12 | D10: =Revenue!D12 | E10: =Revenue!E12 | F10: =SUM(C10:E10)
B11: Settlement Index subscriptions | C11: =Revenue!C14 | D11: =Revenue!D14 | E11: =Revenue!E14 | F11: =SUM(C11:E11)
B12: T-bill yield (protocol's share) | C12: =Revenue!C16 | D12: =Revenue!D16 | E12: =Revenue!E16 | F12: =SUM(C12:E12)
B13: OPERATING REVENUE | C13: =Revenue!C21 | D13: =Revenue!D21 | E13: =Revenue!E21 | F13: =SUM(C13:E13)
B14: Arbitrum grant (one-time, Y1) | C14: =Revenue!C18 | D14: =Revenue!D18 | E14: =Revenue!E18 | F14: =SUM(C14:E14)
B15: TOTAL INFLOWS | C15: =Revenue!C22 | D15: =Revenue!D22 | E15: =Revenue!E22 | F15: =SUM(C15:E15)
B17: EXPENSES
B18: Founder pay | C18: =Expenses!C7 | D18: =Expenses!D7 | E18: =Expenses!E7 | F18: =SUM(C18:E18)
B19: Contractor capacity | C19: =Expenses!C8 | D19: =Expenses!D8 | E19: =Expenses!E8 | F19: =SUM(C19:E19)
B20: Ops stipend | C20: =Expenses!C9 | D20: =Expenses!D9 | E20: =Expenses!E9 | F20: =SUM(C20:E20)
B21: Hosting & infra | C21: =Expenses!C11 | D21: =Expenses!D11 | E21: =Expenses!E11 | F21: =SUM(C21:E21)
B22: CME data license | C22: =Expenses!C12 | D22: =Expenses!D12 | E22: =Expenses!E12 | F22: =SUM(C22:E22)
B23: Customer acquisition (CAC × new partners) | C23: =Expenses!C15 | D23: =Expenses!D15 | E23: =Expenses!E15 | F23: =SUM(C23:E23)
B24: Baseline marketing & promotion | C24: =Expenses!C16 | D24: =Expenses!D16 | E24: =Expenses!E16 | F24: =SUM(C24:E24)
B25: Legal / compliance | C25: =Expenses!C18 | D25: =Expenses!D18 | E25: =Expenses!E18 | F25: =SUM(C25:E25)
B26: Audit costs | C26: =Expenses!C19 | D26: =Expenses!D19 | E26: =Expenses!E19 | F26: =SUM(C26:E26)
B27: Yield paid to staked CURD holders | C27: =Expenses!C21 | D27: =Expenses!D21 | E27: =Expenses!E21 | F27: =SUM(C27:E27)
B28: CME seed (one-time) | C28: =Expenses!C23 | D28: =Expenses!D23 | E28: =Expenses!E23 | F28: =SUM(C28:E28)
B29: Liquidity tranche (one-time) | C29: =Expenses!C24 | D29: =Expenses!D24 | E29: =Expenses!E24 | F29: =SUM(C29:E29)
B30: TOTAL EXPENSES | C30: =Expenses!C27 | D30: =Expenses!D27 | E30: =Expenses!E27 | F30: =SUM(C30:E30)
B32: NET RESULTS
B33: NET OPERATING (Op Revenue − Total Expenses) | C33: =C13-C30 | D33: =D13-D30 | E33: =E13-E30 | F33: =SUM(C33:E33)
B34: NET WITH GRANT (Total Inflows − Total Expenses) | C34: =C15-C30 | D34: =D15-D30 | E34: =E15-E30 | F34: =SUM(C34:E34)

Sheet Cashflow Y1
B2: CASHFLOW — Year 1 (May 2026 – Apr 2027)
B3: Monthly. Grant tranches per milestone schedule.
B5: Line Item | C5: May | D5: Jun | E5: Jul | F5: Aug | G5: Sep | H5: Oct | I5: Nov | J5: Dec | K5: Jan | L5: Feb | M5: Mar | N5: Apr | O5: Total Y1
B6: INFLOWS
B7: Grant tranche | C7: 20000 | D7: 0 | E7: 20000 | F7: 0 | G7: 0 | H7: 20000 | I7: 0 | J7: 0 | K7: 20000 | L7: 0 | M7: 50000 | N7: 20000 | O7: =SUM(C7:N7)
B8: Operating revenue (illustrative ramp) | C8: 200 | D8: 400 | E8: 800 | F8: 1500 | G8: 2500 | H8: 4000 | I8: 6000 | J8: 8000 | K8: 10000 | L8: 12000 | M8: 14000 | N8: 16000 | O8: =SUM(C8:N8)
B9: TOTAL INFLOWS | C9: =C7+C8 | D9: =D7+D8 | E9: =E7+E8 | F9: =F7+F8 | G9: =G7+G8 | H9: =H7+H8 | I9: =I7+I8 | J9: =J7+J8 | ... N9: =N7+N8 | O9: =SUM(C9:N9)
B11: OUTFLOWS
B12: Founder pay | C12: =Assumptions!C43/12 | D12: =Assumptions!C43/12 | E12: =Assumptions!C43/12 | F12: =Assumptions!C43/12 | G12: =Assumptions!C43/12 | H12: =Assumptions!C43/12 | I12: =Assumptions!C43/12 | J12: =Assumptions!C43/12 | K12: =Assumptions!C43/12 | L12: =Assumptions!C43/12 | M12: =Assumptions!C43/12 | N12: =Assumptions!C43/12 | O12: =SUM(C12:N12)
B13: Contractor | C13: =Assumptions!C44/12 | D13: =Assumptions!C44/12 | E13: =Assumptions!C44/12 | F13: =Assumptions!C44/12 | G13: =Assumptions!C44/12 | H13: =Assumptions!C44/12 | I13: =Assumptions!C44/12 | J13: =Assumptions!C44/12 | K13: =Assumptions!C44/12 | L13: =Assumptions!C44/12 | M13: =Assumptions!C44/12 | N13: =Assumptions!C44/12 | O13: =SUM(C13:N13)
B14: Ops stipend | C14: =Assumptions!C45/12 | D14: =Assumptions!C45/12 | E14: =Assumptions!C45/12 | F14: =Assumptions!C45/12 | G14: =Assumptions!C45/12 | H14: =Assumptions!C45/12 | I14: =Assumptions!C45/12 | J14: =Assumptions!C45/12 | K14: =Assumptions!C45/12 | L14: =Assumptions!C45/12 | M14: =Assumptions!C45/12 | N14: =Assumptions!C45/12 | O14: =SUM(C14:N14)
B15: Hosting & infra | C15: =Assumptions!C46/12 | D15: =Assumptions!C46/12 | E15: =Assumptions!C46/12 | F15: =Assumptions!C46/12 | G15: =Assumptions!C46/12 | H15: =Assumptions!C46/12 | I15: =Assumptions!C46/12 | J15: =Assumptions!C46/12 | K15: =Assumptions!C46/12 | L15: =Assumptions!C46/12 | M15: =Assumptions!C46/12 | N15: =Assumptions!C46/12 | O15: =SUM(C15:N15)
B16: Customer acquisition (CAC) | C16: 200 | D16: 200 | E16: 200 | F16: 250 | G16: 250 | H16: 250 | I16: 300 | J16: 300 | K16: 300 | L16: 300 | M16: 300 | N16: 300 | O16: =SUM(C16:N16)
B17: Baseline marketing | C17: 3000 | D17: 3000 | E17: 3000 | F17: 2500 | G17: 2500 | H17: 2500 | I17: 2500 | J17: 2500 | K17: 2500 | L17: 2500 | M17: 2500 | N17: 2500 | O17: =SUM(C17:N17)
B18: Legal / compliance | C18: 500 | D18: 500 | E18: 0 | F18: 1000 | G18: 500 | H18: 0 | I18: 1000 | J18: 500 | K18: 0 | L18: 500 | M18: 500 | N18: 0 | O18: =SUM(C18:N18)
B19: Audit costs | C19: 0 | D19: 0 | E19: 0 | F19: 0 | G19: 0 | H19: 0 | I19: 0 | J19: 0 | K19: 0 | L19: 0 | M19: 6000 | N19: 0 | O19: =SUM(C19:N19)
B20: CME seed (one-time) | C20: 0 | D20: 0 | E20: 0 | F20: 0 | G20: 0 | H20: 0 | I20: 0 | J20: 0 | K20: 0 | L20: 0 | M20: 0 | N20: 8000 | O20: =SUM(C20:N20)
B21: Liquidity tranche | C21: 0 | D21: 0 | E21: 0 | F21: 0 | G21: 0 | H21: 20000 | I21: 0 | J21: 0 | K21: 0 | L21: 0 | M21: 0 | N21: 0 | O21: =SUM(C21:N21)
B22: TOTAL OUTFLOWS | C22: =C12+C13+C14+C15+C16+C17+C18+C19+C20+C21 | D22: =D12+D13+D14+D15+D16+D17+D18+D19+D20+D21 | E22: =E12+E13+E14+E15+E16+E17+E18+E19+E20+E21 | F22: =F12+F13+F14+F15+F16+F17+F18+F19+F20+F21 | G22: =G12+G13+G14+G15+G16+G17+G18+G19+G20+G21 | H22: =H12+H13+H14+H15+H16+H17+H18+H19+H20+H21 | I22: =I12+I13+I14+I15+I16+I17+I18+I19+I20+I21 | J22: =J12+J13+J14+J15+J16+J17+J18+J19+J20+J21 | ... N22: =N12+N13+N14+N15+N16+N17+N18+N19+N20+N21 | O22: =SUM(C22:N22)
B24: NET CASHFLOW
B25: NET MONTHLY (Inflow − Outflow) | C25: =C9-C22 | D25: =D9-D22 | E25: =E9-E22 | F25: =F9-F22 | G25: =G9-G22 | H25: =H9-H22 | I25: =I9-I22 | J25: =J9-J22 | ... N25: =N9-N22 | O25: =SUM(C25:N25)
B26: CUMULATIVE CASH POSITION | C26: =C25 | D26: =C26+D25 | E26: =D26+E25 | F26: =E26+F25 | G26: =F26+G25 | H26: =G26+H25 | I26: =H26+I25 | J26: =I26+J25 | K26: =J26+K25 | ... N26: =M26+N25 | O26: =N26

Sheet Balance Sheet
B2: BALANCE SHEET — Year-end positions
B3: Snapshot of assets, liabilities, and protocol equity at end of each year. CURD-backing-per-token at the bottom.
B5: Line Item | C5: Y1 End | D5: Y2 End | E5: Y3 End | F5: Notes
B6: ASSETS
B7: USDC treasury (cash + T-bill positions) | C7: ='Treasury Flow'!C18 | D7: ='Treasury Flow'!D18 | E7: ='Treasury Flow'!E18 | F7: Closing balance from Treasury Flow
B8: Uniswap CURD/USDC LP position (USDC side) | C8: 10000 | D8: 12000 | E8: 18000 | F8: $20k LP seeded Y1 M6 from grant; appreciates with trading fees
B9: CURD held in protocol treasury (face value @ $1) | C9: =Assumptions!C56 | D9: =Assumptions!D56 | E9: =Assumptions!E56 | F9: Conservative book value — market value rises w/ backing
B10: TOTAL ASSETS | C10: =SUM(C7:C9) | D10: =SUM(D7:D9) | E10: =SUM(E7:E9)
B11: LIABILITIES
B12: Merchant float commitments | C12: =(Assumptions!C7+Assumptions!C8+Assumptions!C9+Assumptions!C10+Assumptions!C11)*1000 | D12: =(Assumptions!D7+Assumptions!D8+Assumptions!D9+Assumptions!D10+Assumptions!D11)*1000 | E12: =(Assumptions!E7+Assumptions!E8+Assumptions!E9+Assumptions!E10+Assumptions!E11)*1000 | F12: =total partners × $1,000 USD float owed back if returned
B13: Advisor vesting (CURD, unvested portion @ $1) | C13: 120000 | D13: 60000 | E13: 0 | F13: 3 advisors × 50k CURD over 18mo w/ 3mo cliff
B14: Founder performance reward (committed, unvested @ $1) | C14: 7500000 | D14: 11250000 | E14: 11250000 | F14: 30M total tied to expansion tranches (A/B/C = 7.5M/11.25M/11.25M). See Tokenomics §3a.
B15: Original founder allocation (20M, unvested portion) | C15: 14580000 | D15: 9580000 | E15: 4580000 | F15: 20M @ 4-yr linear from Mar 25 2026 (FounderVestingWallet to be deployed)
B16: Revenue share owed to ARB DAO (capped 1.5× grant) | C16: =MIN(225000,Revenue!C13*0.05) | D16: =MIN(225000,Revenue!D13*0.05) | E16: =MIN(225000,Revenue!E13*0.05) | F16: 5% of operating revenue, cumulative cap = $225k
B17: TOTAL LIABILITIES | C17: =SUM(C12:C16) | D17: =SUM(D12:D16) | E17: =SUM(E12:E16)
B18: PROTOCOL EQUITY
B19: Protocol equity (Assets − Liabilities) | C19: =C10-C17 | D19: =D10-D17 | E19: =E10-E17 | F19: Net protocol value — supports CURD economic backing
B20: CURD CIRCULATING & BACKING
B21: CURD in circulation (= total supply − treasury held) | C21: =Assumptions!C55-Assumptions!C56 | D21: =Assumptions!D55-Assumptions!D56 | E21: =Assumptions!E55-Assumptions!E56 | F21: From Assumptions sheet
B22: USDC backing per circulating CURD | C22: =(C7+C8)/C21 | D22: =(D7+D8)/D21 | E22: =(E7+E8)/E21 | F22: =(USDC + LP USDC) / circulating CURD
B23: Implied CURD floor value (USDC backing + nominal $1) | C23: =MAX(1,1+C22) | D23: =MAX(1,1+D22) | E23: =MAX(1,1+E22) | F23: Conservative floor = $1 par + USDC backing
B25: MEMO — CONTINGENT / DISCLOSED (not in totals above)
B26: Authorized future supply expansion (max) | C26: 200000000 | D26: 200000000 | E26: 200000000 | F26: Governance-authorized mint, conditional on RWA growth triggers. Not yet exercised.
B27: Founder performance reward — TOTAL pool (vested + unvested) | C27: 15000000 | D27: 15000000 | E27: 15000000 | F27: Liability above shows unvested portion only. Vested CURD is in circulation.

Sheet Scenarios
B2: SCENARIO COMPARISON
B3: Conservative / Base (current Assumptions) / Aggressive — same model, different assumptions.
B5: Driver | C5: Conservative | D5: Base (current) | E5: Aggressive | F5: Notes
B6: PARTNER COUNT (Year 3)
B7: Total partners by EOY3 | C7: 2000 | D7: 44400 | E7: 100000 | F7: Greg's base = 44,400; conservative if AI productivity disappoints
B8: AVG GMV PER PARTNER (Y3)
B9: Vendor monthly | C9: 5000 | D9: 7500 | E9: 12000 | F9: USD
B10: Producer monthly | C10: 3500 | D10: 5000 | E10: 8000 | F10: USD
B11: Processor monthly | C11: 6500 | D11: 9000 | E11: 15000 | F11: USD
B12: Distributor monthly | C12: 10000 | D12: 13000 | E12: 22000 | F12: USD
B13: Merchant monthly | C13: 3500 | D13: 7000 | E13: 12000 | F13: USD
B14: SETTLEMENT INDEX (Y3)
B15: Subscriber protocols | C15: 5 | D15: 10 | E15: 30
B16: Avg monthly fee | C16: 500 | D16: 750 | E16: 1500
B17: FX HEDGE PREMIUM
B18: Premium % per settlement | C18: 0.002 | D18: 0.004 | E18: 0.005 | F18: 20–50bps
B19: CAC ASSUMPTIONS
B20: CAC per partner Y3 | C20: 40 | D20: 20 | E20: 12 | F20: AI productivity assumption
B22: PROJECTED Y3 OPERATING REVENUE (rough) | C22: ~$5M | D22: ~$72M+ | E22: ~$200M | F22: Order-of-magnitude only
B23: PROJECTED Y3 NET (rough) | C23: ~$3M | D23: ~$68M+ | E23: ~$190M | F23: T-bill yield adds upside in all scenarios

Sheet Token Treasury
B2: CURD TREASURY — allocations & movements
B3: Total supply: 200,000,000 CURD. Tracks where each pool sits.
B5: Allocation | C5: Y1 End | D5: Y2 End | E5: Y3 End | F5: Notes
B6: ON-CHAIN POOLS (existing)
B7: Treasury (Gnosis Safe) | C7: 165000000 | D7: 160000000 | E7: 155000000 | F7: Decreases as advisor vesting + LP seeding
B8: BootstrapYieldPool | C8: 5000000 | D8: 4500000 | E8: 4000000 | F8: Decreases as stakers earn yield
B9: CurdDirectSale (loaded) | C9: 9900000 | D9: 8500000 | E9: 3000000 | F9: Sold to direct buyers — see flag below
B10: ProjectSale + Commerce NFT | C10: 0 | D10: 0 | E10: 0 | F10: Operational, doesn't hold balance
B11: PROPOSED NEW ALLOCATIONS
B12: Advisor vesting (3 × 50k) | C12: 150000 | D12: 100000 | E12: 50000 | F12: 18-mo vesting w/ 3-mo cliff
B13: Uniswap CURD/USDC LP | C13: 3000000 | D13: 3000000 | E13: 3000000 | F13: Locked min 12 months from Y1 M6
B14: FxStabilityReserve (USDC) | C14: 0 | D14: 50000 | E14: 150000 | F14: Premium-funded over time
B15: ORIGINAL FOUNDER 20M (retro-vesting via FounderVestingWallet)
B16: Founder original — vested cumulative | C16: 5420000 | D16: 10420000 | E16: 15420000 | F16: 20M @ 4-yr linear from Mar 25 2026 (deployment pending)
B17: Founder original — unvested (= liability) | C17: 14580000 | D17: 9580000 | E17: 4580000 | F17: On Balance Sheet as liability until vested
B18: FOUNDER PERFORMANCE REWARD (30M, tied to expansion tranches)
B19: Tranche A — 7.5M (15% of 50M expansion) | C19: 0 | D19: 7500000 | E19: 7500000 | F19: Trigger: 5K partners + $250M GMV
B20: Tranche B — 11.25M (15% of 75M expansion) | C20: 0 | D20: 0 | E20: 11250000 | F20: Trigger: 25K partners + $1B GMV
B21: Tranche C — 11.25M (15% of 75M expansion) | C21: 0 | D21: 0 | E21: 0 | F21: Trigger: 100K partners + $5B GMV (likely Y4+)
B22: Reward — unvested (= liability) | C22: 7500000 | D22: 11250000 | E22: 11250000 | F22: On Balance Sheet — unvested portion of authorized tranches
B23: AUTHORIZED SUPPLY EXPANSION (governance-gated)
B24: Authorized but unminted (max) | C24: 200000000 | D24: 200000000 | E24: 200000000 | F24: Conditional on RWA growth + Super NFT vote
B25: Tranche A — 50M | C25: 0 | D25: 50000000 | E25: 50000000 | F25: After 5K partners + $250M GMV
B26: Tranche B — 75M | C26: 0 | D26: 0 | E26: 75000000 | F26: After 25K partners + $1B GMV
B27: Tranche C — 75M | C27: 0 | D27: 0 | E27: 0 | F27: After 100K partners + $5B GMV
B28: COMMITTED OUTFLOWS
B29: Merchant float commitments | C29: 53000 | D29: 4410000 | E29: 44400000 | F29: =total partners × $1k float
B30: Revenue share owed to ARB | C30: 0 | D30: see BS | E30: see BS | F30: 5% capped at 1.5× grant ($225k)
B32: ⚠ FLAG: At Y3 = 1M buyers × $350 / $1.18 deflationary = ~297M CURD demand,
B33: which exceeds 200M total supply. Either (a) trim Y3 buyer count,
B34: (b) accept higher CURD price (e.g. $5+ in Y3 → 70M CURD demand, feasible),
B35: or (c) governance vote to mint new CURD supply.
